= Exception and Assertions

There're different kinds of exceptions:

* _Exception class_—Refers to `Throwable` class and all its subclasses.
* _Error classes_—Refers to `Error` class and all its subclasses
* _Runtime exception classes_—Refers to runtime exception classes and error classes
* _Unchecked exception classes_—Refers to runtime exception classes and error classes
* _Checked exception classes_—Refers to all exception classes other than the unchecked
exception classes. Class `Throwable` and any of its subclasses that aren't a subclass
of either `Error` or `RuntimeException` are checked exceptions.

Here's the exception hierarchy:

* `java.lang.Throwable`
** `java.lang.Error`
** `java.lang.Exception`
*** `java.lang.RuntimeException`

== Exercise 6.1

Which answer correctly shows the output of class `TwistThrowsException`?

. `useReadFile`; `readFile`; `FileNotFoundException` thrown at runtime
. `useReadFile`; `FileNotFoundException` thrown at runtime
. Compilation error
. `FileNotFoundException` thrown at runtime
. `useReadFile`; `readFile`

.TwistThrowsException.java
[source,java]
----
import java.io.*;

class TwistThrowsException {

    public void readFile(String file) throws FileNotFoundException { // <2>
        System.out.println("readFile");
        throw new FileNotFoundException(); // <1>
    }

    void useReadFile(String name) throws FileNotFoundException { // <4>
        System.out.println("useReadFile");
        try {
            readFile(name);
        } catch (FileNotFoundException e) { // <3>
            // code
        }
    }

    public static void main(String args[]) {
        new TwistThrowsException).useReadFile("a"); // <5>
    }
}
----
<1> The exception `FileNotFoundException` is instantiated.
<2> It is thrown outside of the method `readFile(String)`.
<3> It is caught by method `useReadFile(String)`.
<4> Method `useReadFile(String)` declares also a `FileNotFoundException`, which is a checked exception.
<5> This method is used inside `main(String[])`, but it is never handled. `main(String[])` need to
  handle it using a try-catch block, or declare it in the method signature. *So the answer is C:
  "Compilation error"*.

== Exercise 6.3

Which answer correctly show the output of class `TestMultiCatch`?

.TestMultiCatch.java
[source,java]
----
import java.io.*;

class Exception1 extends IOException {}
class Exception2 extends Exception {}

class TestMultiCatch {
    public static void main(String args[]) {
        try {
            int a = 10;
            if (a <= 10) {
                throw new Exception1();
            } else {
                throw new Exception2();
            }
        } catch (Exception1 | Exception2 ex) {
            System.out.println(ex);
        }
    }
}
----

. Value similar to `Exception1@96a34`
. Value similar to `Exception2@45a86e`
. `Exception1`
. `Exception2`

The answer is C. An attempt to retrieve the value of a reference
variable itself calls its method `toString()`. The common base class
of classes `Exception1` and `Exception2` is `Exception`. Class
`Exception` inherits class `Throwable`, which overrides method
`toString()`. The default implementation of method `toString()` in
class `Throwable` returns the fully qualified name of the `Throwable`
instance (all `Exception` and `Error` classes) together with its
exception message.
